Traceback (most recent call last):
  File "/Users/juliafiedler/anaconda3/envs/SLI39/lib/python3.9/site-packages/jupyter_cache/executors/utils.py", line 58, in single_nb_execution
    executenb(
  File "/Users/juliafiedler/anaconda3/envs/SLI39/lib/python3.9/site-packages/nbclient/client.py", line 1305, in execute
    return NotebookClient(nb=nb, resources=resources, km=km, **kwargs).execute()
  File "/Users/juliafiedler/anaconda3/envs/SLI39/lib/python3.9/site-packages/jupyter_core/utils/__init__.py", line 162, in wrapped
    return loop.run_until_complete(inner)
  File "/Users/juliafiedler/anaconda3/envs/SLI39/lib/python3.9/asyncio/base_events.py", line 647, in run_until_complete
    return future.result()
  File "/Users/juliafiedler/anaconda3/envs/SLI39/lib/python3.9/site-packages/nbclient/client.py", line 705, in async_execute
    await self.async_execute_cell(
  File "/Users/juliafiedler/anaconda3/envs/SLI39/lib/python3.9/site-packages/nbclient/client.py", line 1058, in async_execute_cell
    await self._check_raise_for_error(cell, cell_index, exec_reply)
  File "/Users/juliafiedler/anaconda3/envs/SLI39/lib/python3.9/site-packages/nbclient/client.py", line 914, in _check_raise_for_error
    raise CellExecutionError.from_cell_and_msg(cell, exec_reply_content)
nbclient.exceptions.CellExecutionError: An error occurred while executing the following cell:
------------------
# import necessary libraries
import numpy as np
import xarray as xr
import datetime as dt
from pathlib import Path
import pandas as pd
import os

# data retrieval libraries
import requests
from urllib.request import urlretrieve #used for downloading files
import json
import copernicus_marine_client as copernicusmarine


# data processing libraries
from scipy import stats

# plotting libraries
import seaborn as sns
import cartopy.crs as ccrs
import cartopy.feature as cfeature
import matplotlib.pyplot as plt

from myst_nb import glue #used for figure numbering when exporting to LaTeX

------------------


[0;31m---------------------------------------------------------------------------[0m
[0;31mModuleNotFoundError[0m                       Traceback (most recent call last)
Cell [0;32mIn[1], line 13[0m
[1;32m     11[0m [38;5;28;01mfrom[39;00m [38;5;21;01murllib[39;00m[38;5;21;01m.[39;00m[38;5;21;01mrequest[39;00m [38;5;28;01mimport[39;00m urlretrieve [38;5;66;03m#used for downloading files[39;00m
[1;32m     12[0m [38;5;28;01mimport[39;00m [38;5;21;01mjson[39;00m
[0;32m---> 13[0m [38;5;28;01mimport[39;00m [38;5;21;01mcopernicus_marine_client[39;00m [38;5;28;01mas[39;00m [38;5;21;01mcopernicusmarine[39;00m
[1;32m     16[0m [38;5;66;03m# data processing libraries[39;00m
[1;32m     17[0m [38;5;28;01mfrom[39;00m [38;5;21;01mscipy[39;00m [38;5;28;01mimport[39;00m stats

[0;31mModuleNotFoundError[0m: No module named 'copernicus_marine_client'

