Traceback (most recent call last):
  File "/Users/juliafiedler/anaconda3/envs/SLindicators/lib/python3.8/site-packages/jupyter_cache/executors/utils.py", line 58, in single_nb_execution
    executenb(
  File "/Users/juliafiedler/anaconda3/envs/SLindicators/lib/python3.8/site-packages/nbclient/client.py", line 1305, in execute
    return NotebookClient(nb=nb, resources=resources, km=km, **kwargs).execute()
  File "/Users/juliafiedler/anaconda3/envs/SLindicators/lib/python3.8/site-packages/jupyter_core/utils/__init__.py", line 173, in wrapped
    return loop.run_until_complete(inner)
  File "/Users/juliafiedler/anaconda3/envs/SLindicators/lib/python3.8/asyncio/base_events.py", line 616, in run_until_complete
    return future.result()
  File "/Users/juliafiedler/anaconda3/envs/SLindicators/lib/python3.8/site-packages/nbclient/client.py", line 705, in async_execute
    await self.async_execute_cell(
  File "/Users/juliafiedler/anaconda3/envs/SLindicators/lib/python3.8/site-packages/nbclient/client.py", line 1058, in async_execute_cell
    await self._check_raise_for_error(cell, cell_index, exec_reply)
  File "/Users/juliafiedler/anaconda3/envs/SLindicators/lib/python3.8/site-packages/nbclient/client.py", line 914, in _check_raise_for_error
    raise CellExecutionError.from_cell_and_msg(cell, exec_reply_content)
nbclient.exceptions.CellExecutionError: An error occurred while executing the following cell:
------------------
# Find all days where sea level exceeds the threshold
flood_day = (SL_daily_max.sea_level > threshold)

SL_daily_max['flood_day'] = flood_day

# Filtering the dataset for flood hours and selecting relevant variables
flood_hours_data = SL_daily_max.where(SL_daily_max.flood_day, drop=True)[['year_storm']]

# Converting the dataset to a DataFrame
flood_days_df = flood_days_data.to_dataframe().reset_index()

# Grouping by 'year_storm' and counting the number of flood days
flood_days_per_year = flood_days_df.groupby('year_storm').size().reset_index(name='flood_days_count')
------------------


[0;31m---------------------------------------------------------------------------[0m
[0;31mNameError[0m                                 Traceback (most recent call last)
Cell [0;32mIn[15], line 10[0m
[1;32m      7[0m flood_hours_data [38;5;241m=[39m SL_daily_max[38;5;241m.[39mwhere(SL_daily_max[38;5;241m.[39mflood_day, drop[38;5;241m=[39m[38;5;28;01mTrue[39;00m)[[[38;5;124m'[39m[38;5;124myear_storm[39m[38;5;124m'[39m]]
[1;32m      9[0m [38;5;66;03m# Converting the dataset to a DataFrame[39;00m
[0;32m---> 10[0m flood_days_df [38;5;241m=[39m [43mflood_days_data[49m[38;5;241m.[39mto_dataframe()[38;5;241m.[39mreset_index()
[1;32m     12[0m [38;5;66;03m# Grouping by 'year_storm' and counting the number of flood days[39;00m
[1;32m     13[0m flood_days_per_year [38;5;241m=[39m flood_days_df[38;5;241m.[39mgroupby([38;5;124m'[39m[38;5;124myear_storm[39m[38;5;124m'[39m)[38;5;241m.[39msize()[38;5;241m.[39mreset_index(name[38;5;241m=[39m[38;5;124m'[39m[38;5;124mflood_days_count[39m[38;5;124m'[39m)

[0;31mNameError[0m: name 'flood_days_data' is not defined

